Traceback (most recent call last):
  File "C:\Users\Peter\.conda\envs\geomod\Lib\site-packages\jupyter_cache\executors\utils.py", line 58, in single_nb_execution
    executenb(
  File "C:\Users\Peter\.conda\envs\geomod\Lib\site-packages\nbclient\client.py", line 1305, in execute
    return NotebookClient(nb=nb, resources=resources, km=km, **kwargs).execute()
           ^^^^^^^^^^^^^^^^^^^^^^^^^^^^^^^^^^^^^^^^^^^^^^^^^^^^^^^^^^^^^^^^^^^^^
  File "C:\Users\Peter\.conda\envs\geomod\Lib\site-packages\jupyter_core\utils\__init__.py", line 166, in wrapped
    return loop.run_until_complete(inner)
           ^^^^^^^^^^^^^^^^^^^^^^^^^^^^^^
  File "C:\Users\Peter\.conda\envs\geomod\Lib\asyncio\base_events.py", line 653, in run_until_complete
    return future.result()
           ^^^^^^^^^^^^^^^
  File "C:\Users\Peter\.conda\envs\geomod\Lib\site-packages\nbclient\client.py", line 705, in async_execute
    await self.async_execute_cell(
  File "C:\Users\Peter\.conda\envs\geomod\Lib\site-packages\nbclient\client.py", line 1058, in async_execute_cell
    await self._check_raise_for_error(cell, cell_index, exec_reply)
  File "C:\Users\Peter\.conda\envs\geomod\Lib\site-packages\nbclient\client.py", line 914, in _check_raise_for_error
    raise CellExecutionError.from_cell_and_msg(cell, exec_reply_content)
nbclient.exceptions.CellExecutionError: An error occurred while executing the following cell:
------------------
from gsd_calculations import calculate_speed_versus_gsd
from myst_nb import glue

for name in ["mavic2pro","mavic3hasselblad"]:
glue(name,calculate_speed_versus_gsd(name))
------------------


[1;36m  Cell [1;32mIn[1], line 5[1;36m[0m
[1;33m    glue(name,calculate_speed_versus_gsd(name))[0m
[1;37m    ^[0m
[1;31mIndentationError[0m[1;31m:[0m expected an indented block after 'for' statement on line 4


